<center><b>异常处理</b></center>



# 异常处理

## 异常处理概述

在Java语言中，异常可以分为两类：Checked异常和Unchecked异常。Unchecked异常包括java.lang.RuntimeException、java.lang.Error以及它们的子类，其他异常都是Checked异常。所有异常都最终继承自java.lang.Throwable。如果一个方法有可能导致Checked异常抛出，则该方法要么需要捕获该异常并妥善处理，要么必须把该异常列在自己的throws子句中，否则无法通过编译。Unchecked异常没有这个限制。请注意，Java虚拟机规范并没有这个规定，这只是Java语言的语法规则。



异常可以由Java虚拟机抛出，也可以由Java代码抛出。当Java虚拟机在运行过程中遇到比较严重的问题时，会抛出java.lang.Error的某个子类，如StackOverflowError、OutOfMemoryError等。程序一般无法从这种异常里恢复，所以在代码中通常也不必关心这类异常。一部分指令在执行过程中会导致Java虚拟机抛出java.lang.RuntimeException的某个子类，如NullPointerException、IndexOutOfBoundsException等。这类异常一般是代码中的bug导致的，需要格外注意。在代码中抛出和处理异常是由athrow指令和方法的异常处理表配合完成的。



在Java 6之前，Oracle的Java编译器使用jsr、jsr_w和ret指令来实现finally子句。从Java 6开始，已经不再使用这些指令。

## 异常抛出

在Java代码中，异常是通过throw关键字抛出的。Java虚拟机规范的3.12节给了一个例子，代码如下：

```java
void cantBeZero(int i) {
    if (i == 0) {
    	throw new TestExc();
    }
}
```

上面的方法编译之后，产生下面的字节码：

```java
iload_1 // 把参数1（i）推入操作数栈顶
ifne 12 // 如果i不等于0，直接执行return指令
new #2 // 创建TestExc实例，把引用推入操作数栈顶
dup // 复制TestExc实例引用
invokespecial #3 // 调用TestExc构造函数（栈顶引用已经作为参数弹出）
athrow // 抛出异常
return // 方法返回
```

从字节码来看，异常对象似乎也只是普通的对象，通过new指令创建，然后调用构造函数进行初始化。这是真的吗？如果查看`java.lang.Exception`或`RuntimeException`的源代码就可以知道，这并不是真的。它们的构造函数都调用了超类`java.lang.Throwable`的构造函数。`Throwable`的构造函数又调用了`fillInStackTrace（）`方法记录Java虚拟机栈信息，这个方法的代码如下：

```java
// java.lang.Throwable
public synchronized Throwable fillInStackTrace() {
    if (stackTrace != null ||
        backtrace != null /* Out of protocol state */ ) {
        fillInStackTrace(0);
        stackTrace = UNASSIGNED_STACK;
    }
    return this;
}
```

`fillInStackTrace()`是用Java写的，必须借助另外一个本地方法才能访问Java虚拟机栈，这个方法就是重载后的`fillInStackTrace(int)`方法，代码如下：

```java
private native Throwable fillInStackTrace(int dummy);
```

也就是说，要想抛出异常，Java虚拟机必须实现这个本地方法。



## 异常处理表

异常处理是通过try-catch句实现的，参考Java虚拟机规范的3.12节，里面有一个例子，代码如下：

```java
void catchOne() {
    try {
    	tryItOut();
    } catch (TestExc e) {
    	handleExc(e);
    }
}
```

上面的方法编译之后，产生下面的字节码：

```java
1 aload_0 // 把局部变量0(this)推入操作数栈顶
2 invokevirtual #4 // 调用tryItOut()方法
4 goto 13 // 如果try{}没有抛出异常，直接执行return指令
7 astore_1 // 否则，异常对象引用在操作数栈顶，把它弹出，并放入局部变量1
8 aload_0 // 把this推入栈顶（将作为handleExc()方法的参数0）
9 aload_1 // 把异常对象引用推入栈顶（将作为handleExc()方法的参数1）
10 invokevirtual #5 // 调用handleExc()方法
13 return // 方法返回
```

从字节码来看，如果没有异常抛出，则会直接goto到return指令，方法正常返回。那么如果有异常抛出，goto和return之间的指令是如何执行的呢？答案是查找方法的异常处理表。异常处理表是Code属性的一部分，它记录了方法是否有能力处理某种异常。回顾一下方法的Code属性，它的结构如下：

```java
Code_attribute {
    u2 attribute_name_index;
    u4 attribute_length;
    u2 max_stack;
    u2 max_locals;
    u4 code_length;
    u1 code[code_length];
    u2 exception_table_length;
    { 	
    	u2 start_pc;
        u2 end_pc;
        u2 handler_pc;
        u2 catch_type;
    } 
    exception_table[exception_table_length];
    u2 attributes_count;
    attribute_info attributes[attributes_count];
}
```

异常处理表的每一项都包含3个信息：处理哪部分代码抛出的异常、哪类异常，以及异常处理代码在哪里。具体来说，start_pc和end_pc可以锁定一部分字节码，这部分字节码对应某个可能抛出异常的try{}代码块。catch_type是个索引，通过它可以从运行时常量池中查到一个类符号引用，解析后的类是个异常类，假定这个类是X。如果位于start_pc和end_pc之间的指令抛出异常x，且x是X（或者X的子类）的实例，handler_pc就指出负责异常处理的catch{}块在哪里。



回到catchOne（）方法，它的异常处理表只有如下一项：

| start_pc | end_pc | handler_pc | catch_type |
| -------- | ------ | ---------- | ---------- |
| 0        | 4      | 7          | TestExc    |

当tryItOut()方法通过athrow指令抛出TestExc异常时，Java虚拟机首先会查找tryItOut()方法的异常处理表，看它能否处理该异常。如果能，则跳转到相应的字节码开始异常处理。假设tryItOut()方法无法处理异常，Java虚拟机会进一步查看它的调用者，也就是catchOne()方法的异常处理表。catchOne()方法刚好可以处理TestExc异常，使catch{}块得以执行。假设catchOne()方法也无法处理TestExc异常，Java虚拟机会继续查找catchOne()的调用者的异常处理表。这个过程会一直继续下去，直到找到某个异常处理项，或者到达Java虚拟机栈的底部。



## athrow指令

athrow属于引用类指令。athrow指令的操作数是一个异常对象引用，从操作数栈弹出。





